[2024-05-06T06:48:25.247+0000] {taskinstance.py:1159} INFO - Dependencies all met for dep_context=non-requeueable deps ti=<TaskInstance: main.train_models_task manual__2024-05-06T06:39:09.160653+00:00 [queued]>
[2024-05-06T06:48:25.263+0000] {taskinstance.py:1159} INFO - Dependencies all met for dep_context=requeueable deps ti=<TaskInstance: main.train_models_task manual__2024-05-06T06:39:09.160653+00:00 [queued]>
[2024-05-06T06:48:25.264+0000] {taskinstance.py:1361} INFO - Starting attempt 2 of 2
[2024-05-06T06:48:25.288+0000] {taskinstance.py:1382} INFO - Executing <Task(PythonOperator): train_models_task> on 2024-05-06 06:39:09.160653+00:00
[2024-05-06T06:48:25.304+0000] {standard_task_runner.py:57} INFO - Started process 302 to run task
[2024-05-06T06:48:25.317+0000] {standard_task_runner.py:84} INFO - Running: ['***', 'tasks', 'run', 'main', 'train_models_task', 'manual__2024-05-06T06:39:09.160653+00:00', '--job-id', '275', '--raw', '--subdir', 'DAGS_FOLDER/main.py', '--cfg-path', '/tmp/tmpkh0fl52q']
[2024-05-06T06:48:25.324+0000] {standard_task_runner.py:85} INFO - Job 275: Subtask train_models_task
[2024-05-06T06:48:25.406+0000] {task_command.py:415} INFO - Running <TaskInstance: main.train_models_task manual__2024-05-06T06:39:09.160653+00:00 [running]> on host 9ab4eda088b1
[2024-05-06T06:48:25.581+0000] {taskinstance.py:1660} INFO - Exporting env vars: AIRFLOW_CTX_DAG_OWNER='***' AIRFLOW_CTX_DAG_ID='main' AIRFLOW_CTX_TASK_ID='train_models_task' AIRFLOW_CTX_EXECUTION_DATE='2024-05-06T06:39:09.160653+00:00' AIRFLOW_CTX_TRY_NUMBER='2' AIRFLOW_CTX_DAG_RUN_ID='manual__2024-05-06T06:39:09.160653+00:00'
[2024-05-06T06:48:25.825+0000] {warnings.py:109} WARNING - /opt/***/dags/main.py:113: UserWarning: pandas only supports SQLAlchemy connectable (engine/connection) or database string URI or sqlite3 DBAPI2 connection. Other DBAPI2 objects are not tested. Please consider using SQLAlchemy.
  df = pd.read_sql_query(query, conn)

[2024-05-06T06:48:29.729+0000] {logging_mixin.py:151} WARNING - 2024/05/06 06:48:29 WARNING mlflow.utils.git_utils: Failed to import Git (the Git executable is probably not on your PATH), so Git SHA is not available. Error: Failed to initialize: Bad git executable.
The git executable must be specified in one of the following ways:
    - be included in your $PATH
    - be set via $GIT_PYTHON_GIT_EXECUTABLE
    - explicitly set via git.refresh(<full-path-to-git-executable>)

All git commands will error until this is rectified.

This initial message can be silenced or aggravated in the future by setting the
$GIT_PYTHON_REFRESH environment variable. Use one of the following values:
    - quiet|q|silence|s|silent|none|n|0: for no message or exception
    - warn|w|warning|log|l|1: for a warning message (logging level CRITICAL, displayed by default)
    - error|e|exception|raise|r|2: for a raised exception

Example:
    export GIT_PYTHON_REFRESH=quiet
[2024-05-06T06:48:30.284+0000] {warnings.py:109} WARNING - /home/***/.local/lib/python3.8/site-packages/joblib/parallel.py:1332: UserWarning: Loky-backed parallel loops cannot be called in a multiprocessing, setting n_jobs=1
  n_jobs = self._backend.configure(n_jobs=self.n_jobs, parallel=self,

[2024-05-06T06:54:50.828+0000] {warnings.py:109} WARNING - /home/***/.local/lib/python3.8/site-packages/_distutils_hack/__init__.py:33: UserWarning: Setuptools is replacing distutils.
  warnings.warn("Setuptools is replacing distutils.")

[2024-05-06T06:54:51.198+0000] {credentials.py:1123} INFO - Found credentials in environment variables.
[2024-05-06T06:54:52.015+0000] {logging_mixin.py:151} WARNING - Registered model 'best_RandomForestClassifier' already exists. Creating a new version of this model...
[2024-05-06T06:54:52.088+0000] {logging_mixin.py:151} WARNING - 2024/05/06 06:54:52 INFO mlflow.tracking._model_registry.client: Waiting up to 300 seconds for model version to finish creation. Model name: best_RandomForestClassifier, version 9
[2024-05-06T06:54:52.088+0000] {logging_mixin.py:151} WARNING - Created version '9' of model 'best_RandomForestClassifier'.
[2024-05-06T06:54:52.118+0000] {taskinstance.py:1943} ERROR - Task failed with exception
Traceback (most recent call last):
  File "/home/airflow/.local/lib/python3.8/site-packages/airflow/operators/python.py", line 192, in execute
    return_value = self.execute_callable()
  File "/home/airflow/.local/lib/python3.8/site-packages/airflow/operators/python.py", line 209, in execute_callable
    return self.python_callable(*self.op_args, **self.op_kwargs)
  File "/opt/airflow/dags/main.py", line 187, in train_models
    mlflow.log_input(datatest, context="demo test data")
AttributeError: module 'mlflow' has no attribute 'log_input'
[2024-05-06T06:54:52.139+0000] {taskinstance.py:1400} INFO - Marking task as FAILED. dag_id=main, task_id=train_models_task, execution_date=20240506T063909, start_date=20240506T064825, end_date=20240506T065452
[2024-05-06T06:54:52.169+0000] {standard_task_runner.py:104} ERROR - Failed to execute job 275 for task train_models_task (module 'mlflow' has no attribute 'log_input'; 302)
[2024-05-06T06:54:52.250+0000] {local_task_job_runner.py:228} INFO - Task exited with return code 1
[2024-05-06T06:54:52.280+0000] {taskinstance.py:2784} INFO - 0 downstream tasks scheduled from follow-on schedule check
