[2024-05-06T13:27:56.201+0000] {taskinstance.py:1159} INFO - Dependencies all met for dep_context=non-requeueable deps ti=<TaskInstance: main.train_models_task manual__2024-05-06T13:25:17.283644+00:00 [queued]>
[2024-05-06T13:27:56.288+0000] {taskinstance.py:1159} INFO - Dependencies all met for dep_context=requeueable deps ti=<TaskInstance: main.train_models_task manual__2024-05-06T13:25:17.283644+00:00 [queued]>
[2024-05-06T13:27:56.289+0000] {taskinstance.py:1361} INFO - Starting attempt 1 of 2
[2024-05-06T13:27:56.349+0000] {taskinstance.py:1382} INFO - Executing <Task(PythonOperator): train_models_task> on 2024-05-06 13:25:17.283644+00:00
[2024-05-06T13:27:56.402+0000] {standard_task_runner.py:57} INFO - Started process 381 to run task
[2024-05-06T13:27:56.421+0000] {standard_task_runner.py:84} INFO - Running: ['***', 'tasks', 'run', 'main', 'train_models_task', 'manual__2024-05-06T13:25:17.283644+00:00', '--job-id', '310', '--raw', '--subdir', 'DAGS_FOLDER/main.py', '--cfg-path', '/tmp/tmpvf0vckn9']
[2024-05-06T13:27:56.442+0000] {standard_task_runner.py:85} INFO - Job 310: Subtask train_models_task
[2024-05-06T13:27:56.745+0000] {task_command.py:415} INFO - Running <TaskInstance: main.train_models_task manual__2024-05-06T13:25:17.283644+00:00 [running]> on host e502cb09ab6c
[2024-05-06T13:27:57.219+0000] {taskinstance.py:1660} INFO - Exporting env vars: AIRFLOW_CTX_DAG_OWNER='***' AIRFLOW_CTX_DAG_ID='main' AIRFLOW_CTX_TASK_ID='train_models_task' AIRFLOW_CTX_EXECUTION_DATE='2024-05-06T13:25:17.283644+00:00' AIRFLOW_CTX_TRY_NUMBER='1' AIRFLOW_CTX_DAG_RUN_ID='manual__2024-05-06T13:25:17.283644+00:00'
[2024-05-06T13:27:57.774+0000] {warnings.py:109} WARNING - /opt/***/dags/main.py:113: UserWarning: pandas only supports SQLAlchemy connectable (engine/connection) or database string URI or sqlite3 DBAPI2 connection. Other DBAPI2 objects are not tested. Please consider using SQLAlchemy.
  df = pd.read_sql_query(query, conn)

[2024-05-06T13:28:01.709+0000] {logging_mixin.py:151} WARNING - 2024/05/06 13:28:01 WARNING mlflow.utils.git_utils: Failed to import Git (the Git executable is probably not on your PATH), so Git SHA is not available. Error: Failed to initialize: Bad git executable.
The git executable must be specified in one of the following ways:
    - be included in your $PATH
    - be set via $GIT_PYTHON_GIT_EXECUTABLE
    - explicitly set via git.refresh(<full-path-to-git-executable>)

All git commands will error until this is rectified.

This initial message can be silenced or aggravated in the future by setting the
$GIT_PYTHON_REFRESH environment variable. Use one of the following values:
    - quiet|q|silence|s|silent|none|n|0: for no message or exception
    - warn|w|warning|log|l|1: for a warning message (logging level CRITICAL, displayed by default)
    - error|e|exception|raise|r|2: for a raised exception

Example:
    export GIT_PYTHON_REFRESH=quiet
[2024-05-06T13:28:05.215+0000] {warnings.py:109} WARNING - /home/***/.local/lib/python3.8/site-packages/joblib/parallel.py:1332: UserWarning: Loky-backed parallel loops cannot be called in a multiprocessing, setting n_jobs=1
  n_jobs = self._backend.configure(n_jobs=self.n_jobs, parallel=self,

[2024-05-06T13:33:04.809+0000] {warnings.py:109} WARNING - /home/***/.local/lib/python3.8/site-packages/_distutils_hack/__init__.py:33: UserWarning: Setuptools is replacing distutils.
  warnings.warn("Setuptools is replacing distutils.")

[2024-05-06T13:33:05.993+0000] {credentials.py:1123} INFO - Found credentials in environment variables.
[2024-05-06T13:33:09.319+0000] {logging_mixin.py:151} WARNING - Registered model 'best_RandomForestClassifier' already exists. Creating a new version of this model...
[2024-05-06T13:33:09.647+0000] {logging_mixin.py:151} WARNING - 2024/05/06 13:33:09 INFO mlflow.tracking._model_registry.client: Waiting up to 300 seconds for model version to finish creation. Model name: best_RandomForestClassifier, version 12
[2024-05-06T13:33:09.648+0000] {logging_mixin.py:151} WARNING - Created version '12' of model 'best_RandomForestClassifier'.
[2024-05-06T13:33:09.744+0000] {logging_mixin.py:151} INFO -         race  gender  ... number_inpatient  number_diagnoses
0  Caucasian  Female  ...                0                 9

[1 rows x 39 columns]
[2024-05-06T13:33:10.197+0000] {warnings.py:109} WARNING - /home/***/.local/lib/python3.8/site-packages/joblib/parallel.py:1332: UserWarning: Loky-backed parallel loops cannot be called in a multiprocessing, setting n_jobs=1
  n_jobs = self._backend.configure(n_jobs=self.n_jobs, parallel=self,

[2024-05-06T13:38:56.981+0000] {logging_mixin.py:151} WARNING - Registered model 'best_DecisionTreeClassifier' already exists. Creating a new version of this model...
[2024-05-06T13:38:57.901+0000] {logging_mixin.py:151} WARNING - 2024/05/06 13:38:57 INFO mlflow.tracking._model_registry.client: Waiting up to 300 seconds for model version to finish creation. Model name: best_DecisionTreeClassifier, version 4
[2024-05-06T13:38:57.904+0000] {logging_mixin.py:151} WARNING - Created version '4' of model 'best_DecisionTreeClassifier'.
[2024-05-06T13:38:58.009+0000] {logging_mixin.py:151} INFO -         race  gender  ... number_inpatient  number_diagnoses
0  Caucasian  Female  ...                0                 9

[1 rows x 39 columns]
[2024-05-06T13:38:58.530+0000] {python.py:194} INFO - Done. Returned value was: None
[2024-05-06T13:38:58.560+0000] {taskinstance.py:1400} INFO - Marking task as SUCCESS. dag_id=main, task_id=train_models_task, execution_date=20240506T132517, start_date=20240506T132756, end_date=20240506T133858
[2024-05-06T13:38:58.693+0000] {local_task_job_runner.py:228} INFO - Task exited with return code 0
[2024-05-06T13:38:58.727+0000] {taskinstance.py:2784} INFO - 0 downstream tasks scheduled from follow-on schedule check
