[2024-05-06T13:21:54.943+0000] {taskinstance.py:1159} INFO - Dependencies all met for dep_context=non-requeueable deps ti=<TaskInstance: main.train_models_task manual__2024-05-06T13:05:38.306171+00:00 [queued]>
[2024-05-06T13:21:55.014+0000] {taskinstance.py:1159} INFO - Dependencies all met for dep_context=requeueable deps ti=<TaskInstance: main.train_models_task manual__2024-05-06T13:05:38.306171+00:00 [queued]>
[2024-05-06T13:21:55.016+0000] {taskinstance.py:1361} INFO - Starting attempt 2 of 2
[2024-05-06T13:21:55.088+0000] {taskinstance.py:1382} INFO - Executing <Task(PythonOperator): train_models_task> on 2024-05-06 13:05:38.306171+00:00
[2024-05-06T13:21:55.126+0000] {standard_task_runner.py:57} INFO - Started process 259 to run task
[2024-05-06T13:21:55.143+0000] {standard_task_runner.py:84} INFO - Running: ['***', 'tasks', 'run', 'main', 'train_models_task', 'manual__2024-05-06T13:05:38.306171+00:00', '--job-id', '305', '--raw', '--subdir', 'DAGS_FOLDER/main.py', '--cfg-path', '/tmp/tmpy4alcwut']
[2024-05-06T13:21:55.152+0000] {standard_task_runner.py:85} INFO - Job 305: Subtask train_models_task
[2024-05-06T13:21:55.487+0000] {task_command.py:415} INFO - Running <TaskInstance: main.train_models_task manual__2024-05-06T13:05:38.306171+00:00 [running]> on host e502cb09ab6c
[2024-05-06T13:21:55.927+0000] {taskinstance.py:1660} INFO - Exporting env vars: AIRFLOW_CTX_DAG_OWNER='***' AIRFLOW_CTX_DAG_ID='main' AIRFLOW_CTX_TASK_ID='train_models_task' AIRFLOW_CTX_EXECUTION_DATE='2024-05-06T13:05:38.306171+00:00' AIRFLOW_CTX_TRY_NUMBER='2' AIRFLOW_CTX_DAG_RUN_ID='manual__2024-05-06T13:05:38.306171+00:00'
[2024-05-06T13:21:56.966+0000] {warnings.py:109} WARNING - /opt/***/dags/main.py:113: UserWarning: pandas only supports SQLAlchemy connectable (engine/connection) or database string URI or sqlite3 DBAPI2 connection. Other DBAPI2 objects are not tested. Please consider using SQLAlchemy.
  df = pd.read_sql_query(query, conn)

[2024-05-06T13:21:57.111+0000] {taskinstance.py:1943} ERROR - Task failed with exception
Traceback (most recent call last):
  File "/home/airflow/.local/lib/python3.8/site-packages/airflow/operators/python.py", line 192, in execute
    return_value = self.execute_callable()
  File "/home/airflow/.local/lib/python3.8/site-packages/airflow/operators/python.py", line 209, in execute_callable
    return self.python_callable(*self.op_args, **self.op_kwargs)
  File "/opt/airflow/dags/main.py", line 177, in train_models
    datatrain = mlflow.data.from_pandas(
AttributeError: module 'mlflow' has no attribute 'data'
[2024-05-06T13:21:57.187+0000] {taskinstance.py:1400} INFO - Marking task as FAILED. dag_id=main, task_id=train_models_task, execution_date=20240506T130538, start_date=20240506T132154, end_date=20240506T132157
[2024-05-06T13:21:57.301+0000] {standard_task_runner.py:104} ERROR - Failed to execute job 305 for task train_models_task (module 'mlflow' has no attribute 'data'; 259)
[2024-05-06T13:21:57.341+0000] {local_task_job_runner.py:228} INFO - Task exited with return code 1
[2024-05-06T13:21:57.457+0000] {taskinstance.py:2784} INFO - 0 downstream tasks scheduled from follow-on schedule check
