[2024-05-06T05:54:47.669+0000] {taskinstance.py:1159} INFO - Dependencies all met for dep_context=non-requeueable deps ti=<TaskInstance: main.train_models_task manual__2024-05-06T05:53:38.941685+00:00 [queued]>
[2024-05-06T05:54:47.688+0000] {taskinstance.py:1159} INFO - Dependencies all met for dep_context=requeueable deps ti=<TaskInstance: main.train_models_task manual__2024-05-06T05:53:38.941685+00:00 [queued]>
[2024-05-06T05:54:47.688+0000] {taskinstance.py:1361} INFO - Starting attempt 1 of 2
[2024-05-06T05:54:47.710+0000] {taskinstance.py:1382} INFO - Executing <Task(PythonOperator): train_models_task> on 2024-05-06 05:53:38.941685+00:00
[2024-05-06T05:54:47.726+0000] {standard_task_runner.py:57} INFO - Started process 131 to run task
[2024-05-06T05:54:47.735+0000] {standard_task_runner.py:84} INFO - Running: ['***', 'tasks', 'run', 'main', 'train_models_task', 'manual__2024-05-06T05:53:38.941685+00:00', '--job-id', '255', '--raw', '--subdir', 'DAGS_FOLDER/main.py', '--cfg-path', '/tmp/tmpmzfvv57m']
[2024-05-06T05:54:47.741+0000] {standard_task_runner.py:85} INFO - Job 255: Subtask train_models_task
[2024-05-06T05:54:47.844+0000] {task_command.py:415} INFO - Running <TaskInstance: main.train_models_task manual__2024-05-06T05:53:38.941685+00:00 [running]> on host 9ab4eda088b1
[2024-05-06T05:54:48.019+0000] {taskinstance.py:1660} INFO - Exporting env vars: AIRFLOW_CTX_DAG_OWNER='***' AIRFLOW_CTX_DAG_ID='main' AIRFLOW_CTX_TASK_ID='train_models_task' AIRFLOW_CTX_EXECUTION_DATE='2024-05-06T05:53:38.941685+00:00' AIRFLOW_CTX_TRY_NUMBER='1' AIRFLOW_CTX_DAG_RUN_ID='manual__2024-05-06T05:53:38.941685+00:00'
[2024-05-06T05:54:49.654+0000] {warnings.py:109} WARNING - /opt/***/dags/main.py:113: UserWarning: pandas only supports SQLAlchemy connectable (engine/connection) or database string URI or sqlite3 DBAPI2 connection. Other DBAPI2 objects are not tested. Please consider using SQLAlchemy.
  df = pd.read_sql_query(query, conn)

[2024-05-06T05:54:51.556+0000] {logging_mixin.py:151} WARNING - 2024/05/06 05:54:51 WARNING mlflow.utils.git_utils: Failed to import Git (the Git executable is probably not on your PATH), so Git SHA is not available. Error: Failed to initialize: Bad git executable.
The git executable must be specified in one of the following ways:
    - be included in your $PATH
    - be set via $GIT_PYTHON_GIT_EXECUTABLE
    - explicitly set via git.refresh(<full-path-to-git-executable>)

All git commands will error until this is rectified.

This initial message can be silenced or aggravated in the future by setting the
$GIT_PYTHON_REFRESH environment variable. Use one of the following values:
    - quiet|q|silence|s|silent|none|n|0: for no message or exception
    - warn|w|warning|log|l|1: for a warning message (logging level CRITICAL, displayed by default)
    - error|e|exception|raise|r|2: for a raised exception

Example:
    export GIT_PYTHON_REFRESH=quiet
[2024-05-06T05:54:52.895+0000] {warnings.py:109} WARNING - /home/***/.local/lib/python3.8/site-packages/joblib/parallel.py:1332: UserWarning: Loky-backed parallel loops cannot be called in a multiprocessing, setting n_jobs=1
  n_jobs = self._backend.configure(n_jobs=self.n_jobs, parallel=self,

[2024-05-06T05:57:51.725+0000] {warnings.py:109} WARNING - /home/***/.local/lib/python3.8/site-packages/_distutils_hack/__init__.py:33: UserWarning: Setuptools is replacing distutils.
  warnings.warn("Setuptools is replacing distutils.")

[2024-05-06T05:57:52.360+0000] {credentials.py:1123} INFO - Found credentials in environment variables.
[2024-05-06T05:57:52.909+0000] {logging_mixin.py:151} WARNING - Registered model 'best_RandomForestClassifier' already exists. Creating a new version of this model...
[2024-05-06T05:57:52.985+0000] {logging_mixin.py:151} WARNING - 2024/05/06 05:57:52 INFO mlflow.tracking._model_registry.client: Waiting up to 300 seconds for model version to finish creation. Model name: best_RandomForestClassifier, version 3
[2024-05-06T05:57:52.986+0000] {logging_mixin.py:151} WARNING - Created version '3' of model 'best_RandomForestClassifier'.
[2024-05-06T05:57:53.068+0000] {warnings.py:109} WARNING - /home/***/.local/lib/python3.8/site-packages/joblib/parallel.py:1332: UserWarning: Loky-backed parallel loops cannot be called in a multiprocessing, setting n_jobs=1
  n_jobs = self._backend.configure(n_jobs=self.n_jobs, parallel=self,

[2024-05-06T06:01:12.309+0000] {logging_mixin.py:151} WARNING - Registered model 'best_DecisionTreeClassifier' already exists. Creating a new version of this model...
[2024-05-06T06:01:12.378+0000] {logging_mixin.py:151} WARNING - 2024/05/06 06:01:12 INFO mlflow.tracking._model_registry.client: Waiting up to 300 seconds for model version to finish creation. Model name: best_DecisionTreeClassifier, version 3
[2024-05-06T06:01:12.379+0000] {logging_mixin.py:151} WARNING - Created version '3' of model 'best_DecisionTreeClassifier'.
[2024-05-06T06:01:12.755+0000] {python.py:194} INFO - Done. Returned value was: None
[2024-05-06T06:01:12.779+0000] {taskinstance.py:1400} INFO - Marking task as SUCCESS. dag_id=main, task_id=train_models_task, execution_date=20240506T055338, start_date=20240506T055447, end_date=20240506T060112
[2024-05-06T06:01:12.899+0000] {local_task_job_runner.py:228} INFO - Task exited with return code 0
[2024-05-06T06:01:12.936+0000] {taskinstance.py:2784} INFO - 0 downstream tasks scheduled from follow-on schedule check
