[2024-05-06T01:20:18.666+0000] {taskinstance.py:1159} INFO - Dependencies all met for dep_context=non-requeueable deps ti=<TaskInstance: main.write_to_raw_data_task manual__2024-05-06T01:20:13.025537+00:00 [queued]>
[2024-05-06T01:20:18.685+0000] {taskinstance.py:1159} INFO - Dependencies all met for dep_context=requeueable deps ti=<TaskInstance: main.write_to_raw_data_task manual__2024-05-06T01:20:13.025537+00:00 [queued]>
[2024-05-06T01:20:18.686+0000] {taskinstance.py:1361} INFO - Starting attempt 1 of 2
[2024-05-06T01:20:18.706+0000] {taskinstance.py:1382} INFO - Executing <Task(PythonOperator): write_to_raw_data_task> on 2024-05-06 01:20:13.025537+00:00
[2024-05-06T01:20:18.721+0000] {standard_task_runner.py:57} INFO - Started process 101 to run task
[2024-05-06T01:20:18.730+0000] {standard_task_runner.py:84} INFO - Running: ['***', 'tasks', 'run', 'main', 'write_to_raw_data_task', 'manual__2024-05-06T01:20:13.025537+00:00', '--job-id', '199', '--raw', '--subdir', 'DAGS_FOLDER/main.py', '--cfg-path', '/tmp/tmpyl2aa0lc']
[2024-05-06T01:20:18.736+0000] {standard_task_runner.py:85} INFO - Job 199: Subtask write_to_raw_data_task
[2024-05-06T01:20:18.831+0000] {task_command.py:415} INFO - Running <TaskInstance: main.write_to_raw_data_task manual__2024-05-06T01:20:13.025537+00:00 [running]> on host a752d0c89925
[2024-05-06T01:20:18.991+0000] {taskinstance.py:1660} INFO - Exporting env vars: AIRFLOW_CTX_DAG_OWNER='***' AIRFLOW_CTX_DAG_ID='main' AIRFLOW_CTX_TASK_ID='write_to_raw_data_task' AIRFLOW_CTX_EXECUTION_DATE='2024-05-06T01:20:13.025537+00:00' AIRFLOW_CTX_TRY_NUMBER='1' AIRFLOW_CTX_DAG_RUN_ID='manual__2024-05-06T01:20:13.025537+00:00'
[2024-05-06T01:22:37.651+0000] {taskinstance.py:1943} ERROR - Task failed with exception
Traceback (most recent call last):
  File "/home/airflow/.local/lib/python3.8/site-packages/mysql/connector/connection_cext.py", line 302, in _open_connection
    self._cmysql.connect(**cnx_kwargs)
_mysql_connector.MySQLInterfaceError: Can't connect to MySQL server on '10.64.140.43:3306' (110)

The above exception was the direct cause of the following exception:

Traceback (most recent call last):
  File "/home/airflow/.local/lib/python3.8/site-packages/airflow/operators/python.py", line 192, in execute
    return_value = self.execute_callable()
  File "/home/airflow/.local/lib/python3.8/site-packages/airflow/operators/python.py", line 209, in execute_callable
    return self.python_callable(*self.op_args, **self.op_kwargs)
  File "/opt/airflow/dags/main.py", line 42, in write_to_raw_data
    conn = mysql.connector.connect(
  File "/home/airflow/.local/lib/python3.8/site-packages/mysql/connector/pooling.py", line 293, in connect
    return CMySQLConnection(*args, **kwargs)
  File "/home/airflow/.local/lib/python3.8/site-packages/mysql/connector/connection_cext.py", line 128, in __init__
    self.connect(**kwargs)
  File "/home/airflow/.local/lib/python3.8/site-packages/mysql/connector/abstracts.py", line 1217, in connect
    self._open_connection()
  File "/home/airflow/.local/lib/python3.8/site-packages/mysql/connector/connection_cext.py", line 307, in _open_connection
    raise get_mysql_exception(
mysql.connector.errors.DatabaseError: 2003 (HY000): Can't connect to MySQL server on '10.64.140.43:3306' (110)
[2024-05-06T01:22:37.710+0000] {taskinstance.py:1400} INFO - Marking task as UP_FOR_RETRY. dag_id=main, task_id=write_to_raw_data_task, execution_date=20240506T012013, start_date=20240506T012018, end_date=20240506T012237
[2024-05-06T01:22:37.754+0000] {standard_task_runner.py:104} ERROR - Failed to execute job 199 for task write_to_raw_data_task (2003 (HY000): Can't connect to MySQL server on '10.64.140.43:3306' (110); 101)
[2024-05-06T01:22:37.837+0000] {local_task_job_runner.py:228} INFO - Task exited with return code 1
[2024-05-06T01:22:37.908+0000] {taskinstance.py:2784} INFO - 0 downstream tasks scheduled from follow-on schedule check
