[2024-05-06T04:18:36.063+0000] {taskinstance.py:1159} INFO - Dependencies all met for dep_context=non-requeueable deps ti=<TaskInstance: main.train_models_task manual__2024-05-06T04:16:39.417445+00:00 [queued]>
[2024-05-06T04:18:36.092+0000] {taskinstance.py:1159} INFO - Dependencies all met for dep_context=requeueable deps ti=<TaskInstance: main.train_models_task manual__2024-05-06T04:16:39.417445+00:00 [queued]>
[2024-05-06T04:18:36.093+0000] {taskinstance.py:1361} INFO - Starting attempt 2 of 2
[2024-05-06T04:18:36.117+0000] {taskinstance.py:1382} INFO - Executing <Task(PythonOperator): train_models_task> on 2024-05-06 04:16:39.417445+00:00
[2024-05-06T04:18:36.141+0000] {standard_task_runner.py:57} INFO - Started process 740 to run task
[2024-05-06T04:18:36.156+0000] {standard_task_runner.py:84} INFO - Running: ['***', 'tasks', 'run', 'main', 'train_models_task', 'manual__2024-05-06T04:16:39.417445+00:00', '--job-id', '220', '--raw', '--subdir', 'DAGS_FOLDER/main.py', '--cfg-path', '/tmp/tmp2llcbvpf']
[2024-05-06T04:18:36.166+0000] {standard_task_runner.py:85} INFO - Job 220: Subtask train_models_task
[2024-05-06T04:18:36.309+0000] {task_command.py:415} INFO - Running <TaskInstance: main.train_models_task manual__2024-05-06T04:16:39.417445+00:00 [running]> on host 6a3971e82789
[2024-05-06T04:18:36.527+0000] {taskinstance.py:1660} INFO - Exporting env vars: AIRFLOW_CTX_DAG_OWNER='***' AIRFLOW_CTX_DAG_ID='main' AIRFLOW_CTX_TASK_ID='train_models_task' AIRFLOW_CTX_EXECUTION_DATE='2024-05-06T04:16:39.417445+00:00' AIRFLOW_CTX_TRY_NUMBER='2' AIRFLOW_CTX_DAG_RUN_ID='manual__2024-05-06T04:16:39.417445+00:00'
[2024-05-06T04:18:36.638+0000] {taskinstance.py:1943} ERROR - Task failed with exception
Traceback (most recent call last):
  File "/home/airflow/.local/lib/python3.8/site-packages/airflow/operators/python.py", line 192, in execute
    return_value = self.execute_callable()
  File "/home/airflow/.local/lib/python3.8/site-packages/airflow/operators/python.py", line 209, in execute_callable
    return self.python_callable(*self.op_args, **self.op_kwargs)
  File "/opt/airflow/dags/main.py", line 99, in train_models
    mlflow.set_experiment("mlflow_tracking_examples")
  File "/home/airflow/.local/lib/python3.8/site-packages/mlflow/tracking/fluent.py", line 133, in set_experiment
    raise MlflowException(
mlflow.exceptions.MlflowException: Cannot set a deleted experiment 'mlflow_tracking_examples' as the active experiment. You can restore the experiment, or permanently delete the experiment to create a new one.
[2024-05-06T04:18:36.662+0000] {taskinstance.py:1400} INFO - Marking task as FAILED. dag_id=main, task_id=train_models_task, execution_date=20240506T041639, start_date=20240506T041836, end_date=20240506T041836
[2024-05-06T04:18:36.692+0000] {standard_task_runner.py:104} ERROR - Failed to execute job 220 for task train_models_task (Cannot set a deleted experiment 'mlflow_tracking_examples' as the active experiment. You can restore the experiment, or permanently delete the experiment to create a new one.; 740)
[2024-05-06T04:18:36.727+0000] {local_task_job_runner.py:228} INFO - Task exited with return code 1
[2024-05-06T04:18:36.785+0000] {taskinstance.py:2784} INFO - 0 downstream tasks scheduled from follow-on schedule check
